<?xml version="1.0" encoding="utf-8"?>
<!-- This URDF was automatically created by SolidWorks to URDF Exporter! Originally created by Stephen Brawner (brawner@gmail.com) 
     Commit Version: 1.6.0-4-g7f85cfe  Build Version: 1.6.7995.38578
     For more information, please see http://wiki.ros.org/sw_urdf_exporter -->
<robot
  name="friday">
  <link
    name="base_link">
    <inertial>
      <origin
        xyz="0.0067678 -0.00099543 -0.0094041"
        rpy="0 0 0" />
      <mass
        value="0.5038" />
      <inertia
        ixx="0.00062863"
        ixy="9.3322E-07"
        ixz="-5.8508E-06"
        iyy="0.00057026"
        iyz="-4.0858E-07"
        izz="0.00087254" />
    </inertial>
    <visual>
      <origin
        xyz="0 0 0"
        rpy="0 0 0" />
      <geometry>
        <mesh
          filename="package://champ_description/meshes/base_link.STL" />
      </geometry>
      <material
        name="">
        <color
          rgba="0.9098 0.67843 0.13725 1" />
      </material>
    </visual>
    <collision>
      <origin
        xyz="0 0 0"
        rpy="0 0 0" />
      <geometry>
        <mesh
          filename="package://champ_description/meshes/base_link.STL" />
      </geometry>
    </collision>
  </link>
  <link
    name="fl_abad_link">
    <inertial>
      <origin
        xyz="0.0012078 0.00097058 -0.0069082"
        rpy="0 0 0" />
      <mass
        value="0.089265" />
      <inertia
        ixx="3.0721E-05"
        ixy="6.1399E-10"
        ixz="3.6535E-07"
        iyy="4.0211E-05"
        iyz="1.4431E-07"
        izz="1.628E-05" />
    </inertial>
    <visual>
      <origin
        xyz="0 0 0"
        rpy="0 0 0" />
      <geometry>
        <mesh
          filename="package://champ_description/meshes/fl_abad_link.STL" />
      </geometry>
      <material
        name="">
        <color
          rgba="0.79216 0.81961 0.93333 1" />
      </material>
    </visual>
    <collision>
      <origin
        xyz="0 0 0"
        rpy="0 0 0" />
      <geometry>
        <mesh
          filename="package://champ_description/meshes/fl_abad_link.STL" />
      </geometry>
    </collision>
  </link>
  <joint
    name="fl_abad_joint"
    type="revolute">
    <origin
      xyz="0.093784 0.039 0"
      rpy="0 0 0" />
    <parent
      link="base_link" />
    <child
      link="fl_abad_link" />
    <axis
      xyz="1 0 0" />
    <limit
      lower="-0.67"
      upper="0.85"
      effort="0"
      velocity="0" />
  </joint>
  <link
    name="fl_upper_leg_link">
    <inertial>
      <origin
        xyz="0.0016892 -0.002254 -0.039521"
        rpy="0 0 0" />
      <mass
        value="0.13978" />
      <inertia
        ixx="0.00010981"
        ixy="-1.5028E-06"
        ixz="-6.7166E-07"
        iyy="0.00010346"
        iyz="-9.6645E-07"
        izz="2.8421E-05" />
    </inertial>
    <visual>
      <origin
        xyz="0 0 0"
        rpy="0 0 0" />
      <geometry>
        <mesh
          filename="package://champ_description/meshes/fl_upper_leg_link.STL" />
      </geometry>
      <material
        name="">
        <color
          rgba="0.79216 0.81961 0.93333 1" />
      </material>
    </visual>
    <collision>
      <origin
        xyz="0 0 0"
        rpy="0 0 0" />
      <geometry>
        <mesh
          filename="package://champ_description/meshes/fl_upper_leg_link.STL" />
      </geometry>
    </collision>
  </link>
  <joint
    name="fl_hip_joint"
    type="revolute">
    <origin
      xyz="0 0.06015 -0.01025"
      rpy="0 0 0" />
    <parent
      link="fl_abad_link" />
    <child
      link="fl_upper_leg_link" />
    <axis
      xyz="0 1 0" />
    <limit
      lower="-1.75"
      upper="1.75"
      effort="0"
      velocity="0" />
  </joint>
  <link
    name="fl_lower_leg_link">
    <inertial>
      <origin
        xyz="-0.00068444 0.0013308 -0.029593"
        rpy="0 0 0" />
      <mass
        value="0.060883" />
      <inertia
        ixx="7.5625E-05"
        ixy="3.1107E-07"
        ixz="3.9385E-06"
        iyy="7.2962E-05"
        iyz="-3.0903E-06"
        izz="9.3716E-06" />
    </inertial>
    <visual>
      <origin
        xyz="0 0 0"
        rpy="0 0 0" />
      <geometry>
        <mesh
          filename="package://champ_description/meshes/fl_lower_leg_link.STL" />
      </geometry>
      <material
        name="">
        <color
          rgba="0.098039 0.098039 0.098039 1" />
      </material>
    </visual>
    <collision>
      <origin
        xyz="0 0 0"
        rpy="0 0 0" />
      <geometry>
        <mesh
          filename="package://champ_description/meshes/fl_lower_leg_link.STL" />
      </geometry>
    </collision>
  </link>
  <joint
    name="fl_knee_joint"
    type="revolute">
    <origin
      xyz="0.03 0 -0.107"
      rpy="0 0 0" />
    <parent
      link="fl_upper_leg_link" />
    <child
      link="fl_lower_leg_link" />
    <axis
      xyz="0 1 0" />
    <limit
      lower="-3.14"
      upper="0.0"
      effort="0"
      velocity="0" />
  </joint>
  <link
    name="fl_foot_link">
    <inertial>
      <origin
        xyz="-0.00268456051833178 3.34520542134842E-07 0.011345759540596"
        rpy="0 0 0" />
      <mass
        value="0.00827881665716705" />
      <inertia
        ixx="8.22036221200532E-07"
        ixy="-3.12294267863575E-12"
        ixz="2.06223465353849E-07"
        iyy="1.04877001633808E-06"
        iyz="-3.16711397785252E-12"
        izz="1.31417688803059E-06" />
    </inertial>
    <visual>
      <origin
        xyz="0 0 0"
        rpy="0 0 0" />
      <geometry>
        <mesh
          filename="package://champ_description/meshes/fl_foot_link.STL" />
      </geometry>
      <material
        name="">
        <color
          rgba="0.792156862745098 0.819607843137255 0.933333333333333 1" />
      </material>
    </visual>
    <collision>
      <origin
        xyz="0 0 0"
        rpy="0 0 0" />
      <geometry>
        <mesh
          filename="package://champ_description/meshes/fl_foot_link.STL" />
      </geometry>
    </collision>
  </link>
  <joint
    name="fl_ankle_joint"
    type="fixed">
    <origin
      xyz="-0.00045854 0.0016595 -0.13599"
      rpy="0 0 0" />
    <parent
      link="fl_lower_leg_link" />
    <child
      link="fl_foot_link" />
    <axis
      xyz="0 0 0" />
  </joint>
  <link
    name="fr_abad_link">
    <inertial>
      <origin
        xyz="0.000100804801752744 -0.00768686244926658 -0.00572309756879297"
        rpy="0 0 0" />
      <mass
        value="0.0710934661015296" />
      <inertia
        ixx="2.16837396661824E-05"
        ixy="-5.13092491322846E-07"
        ixz="2.67173869918524E-07"
        iyy="2.92711773680173E-05"
        iyz="-2.20334549485813E-08"
        izz="1.22638110482517E-05" />
    </inertial>
    <visual>
      <origin
        xyz="0 0 0"
        rpy="0 0 0" />
      <geometry>
        <mesh
          filename="package://champ_description/meshes/fr_abad_link.STL" />
      </geometry>
      <material
        name="">
        <color
          rgba="0.792156862745098 0.819607843137255 0.933333333333333 1" />
      </material>
    </visual>
    <collision>
      <origin
        xyz="0 0 0"
        rpy="0 0 0" />
      <geometry>
        <mesh
          filename="package://champ_description/meshes/fr_abad_link.STL" />
      </geometry>
    </collision>
  </link>
  <joint
    name="fr_abad_joint"
    type="revolute">
    <origin
      xyz="0.093784 -0.039 0"
      rpy="0 0 0" />
    <parent
      link="base_link" />
    <child
      link="fr_abad_link" />
    <axis
      xyz="1 0 0" />
    <limit
      lower="-0.85"
      upper="0.67"
      effort="0"
      velocity="0" />
  </joint>
  <link
    name="fr_upper_leg_linnk">
    <inertial>
      <origin
        xyz="0.0025972 0.00091552 -0.043088"
        rpy="0 0 0" />
      <mass
        value="0.24625" />
      <inertia
        ixx="0.00021105"
        ixy="-5.8956E-13"
        ixz="4.4955E-06"
        iyy="0.00020129"
        iyz="2.1283E-06"
        izz="5.171E-05" />
    </inertial>
    <visual>
      <origin
        xyz="0 0 0"
        rpy="0 0 0" />
      <geometry>
        <mesh
          filename="package://champ_description/meshes/fr_upper_leg_linnk.STL" />
      </geometry>
      <material
        name="">
        <color
          rgba="0.79216 0.81961 0.93333 1" />
      </material>
    </visual>
    <collision>
      <origin
        xyz="0 0 0"
        rpy="0 0 0" />
      <geometry>
        <mesh
          filename="package://champ_description/meshes/fr_upper_leg_linnk.STL" />
      </geometry>
    </collision>
  </link>
  <joint
    name="fr_hip_joint"
    type="revolute">
    <origin
      xyz="0 -0.06015 -0.01005"
      rpy="0 0 0" />
    <parent
      link="fr_abad_link" />
    <child
      link="fr_upper_leg_linnk" />
    <axis
      xyz="0 1 0" />
    <limit
      lower="-1.75"
      upper="1.75"
      effort="0"
      velocity="0" />
  </joint>
  <link
    name="fr_lower_leg_link">
    <inertial>
      <origin
        xyz="-0.00068446602124661 -0.00133084696142388 -0.029592973719876"
        rpy="0 0 0" />
      <mass
        value="0.0608832342298749" />
      <inertia
        ixx="7.56255610630119E-05"
        ixy="-3.11064157488279E-07"
        ixz="3.93850946693039E-06"
        iyy="7.29623913211003E-05"
        iyz="3.09026720482322E-06"
        izz="9.37165067008371E-06" />
    </inertial>
    <visual>
      <origin
        xyz="0 0 0"
        rpy="0 0 0" />
      <geometry>
        <mesh
          filename="package://champ_description/meshes/fr_lower_leg_link.STL" />
      </geometry>
      <material
        name="">
        <color
          rgba="0.0980392156862745 0.0980392156862745 0.0980392156862745 1" />
      </material>
    </visual>
    <collision>
      <origin
        xyz="0 0 0"
        rpy="0 0 0" />
      <geometry>
        <mesh
          filename="package://champ_description/meshes/fr_lower_leg_link.STL" />
      </geometry>
    </collision>
  </link>
  <joint
    name="fr_knee_joint"
    type="revolute">
    <origin
      xyz="0.03 0 -0.107"
      rpy="0 0 0" />
    <parent
      link="fr_upper_leg_linnk" />
    <child
      link="fr_lower_leg_link" />
    <axis
      xyz="0 1 0" />
    <limit
      lower="-3.14"
      upper="0.0"
      effort="0"
      velocity="0" />
  </joint>
  <link
    name="fr_foot_link">
    <inertial>
      <origin
        xyz="-0.0026845605183318 3.34520542100147E-07 0.0113457595405959"
        rpy="0 0 0" />
      <mass
        value="0.00827881665716705" />
      <inertia
        ixx="8.22036221200532E-07"
        ixy="-3.1229426786921E-12"
        ixz="2.06223465353849E-07"
        iyy="1.04877001633807E-06"
        iyz="-3.16711397780049E-12"
        izz="1.31417688803058E-06" />
    </inertial>
    <visual>
      <origin
        xyz="0 0 0"
        rpy="0 0 0" />
      <geometry>
        <mesh
          filename="package://champ_description/meshes/fr_foot_link.STL" />
      </geometry>
      <material
        name="">
        <color
          rgba="0.792156862745098 0.819607843137255 0.933333333333333 1" />
      </material>
    </visual>
    <collision>
      <origin
        xyz="0 0 0"
        rpy="0 0 0" />
      <geometry>
        <mesh
          filename="package://champ_description/meshes/fr_foot_link.STL" />
      </geometry>
    </collision>
  </link>
  <joint
    name="fr_ankle_joint"
    type="fixed">
    <origin
      xyz="-0.00045854 -0.0016595 -0.13599"
      rpy="0 0 0" />
    <parent
      link="fr_lower_leg_link" />
    <child
      link="fr_foot_link" />
    <axis
      xyz="0 0 0" />
  </joint>
  <link
    name="hr_abad_link">
    <inertial>
      <origin
        xyz="0.000100308272320632 -0.00768686894466022 -0.00572309756879935"
        rpy="0 0 0" />
      <mass
        value="0.0710934661015759" />
      <inertia
        ixx="2.16836734119059E-05"
        ixy="-5.12602380112022E-07"
        ixz="2.67172446122063E-07"
        iyy="2.92712436222949E-05"
        iyz="-2.20507128710183E-08"
        izz="1.22638110482607E-05" />
    </inertial>
    <visual>
      <origin
        xyz="0 0 0"
        rpy="0 0 0" />
      <geometry>
        <mesh
          filename="package://champ_description/meshes/hr_abad_link.STL" />
      </geometry>
      <material
        name="">
        <color
          rgba="0.792156862745098 0.819607843137255 0.933333333333333 1" />
      </material>
    </visual>
    <collision>
      <origin
        xyz="0 0 0"
        rpy="0 0 0" />
      <geometry>
        <mesh
          filename="package://champ_description/meshes/hr_abad_link.STL" />
      </geometry>
    </collision>
  </link>
  <joint
    name="hr_abad_joint"
    type="revolute">
    <origin
      xyz="-0.090715 -0.039 0"
      rpy="0 0 0" />
    <parent
      link="base_link" />
    <child
      link="hr_abad_link" />
    <axis
      xyz="1 0 0" />
    <limit
      lower="-0.85"
      upper="0.67"
      effort="0"
      velocity="0" />
  </joint>
  <link
    name="hr_upper_leg_link">
    <inertial>
      <origin
        xyz="0.00259724502217444 0.000809047775928828 -0.0430878024421885"
        rpy="0 0 0" />
      <mass
        value="0.246251887843439" />
      <inertia
        ixx="0.000211052742715009"
        ixy="-9.72639899823502E-13"
        ixz="4.4954855470395E-06"
        iyy="0.000201293863856898"
        iyz="2.12832092364886E-06"
        izz="5.17101630303781E-05" />
    </inertial>
    <visual>
      <origin
        xyz="0 0 0"
        rpy="0 0 0" />
      <geometry>
        <mesh
          filename="package://champ_description/meshes/hr_upper_leg_link.STL" />
      </geometry>
      <material
        name="">
        <color
          rgba="0.792156862745098 0.819607843137255 0.933333333333333 1" />
      </material>
    </visual>
    <collision>
      <origin
        xyz="0 0 0"
        rpy="0 0 0" />
      <geometry>
        <mesh
          filename="package://champ_description/meshes/hr_upper_leg_link.STL" />
      </geometry>
    </collision>
  </link>
  <joint
    name="hr_hip_joint"
    type="revolute">
    <origin
      xyz="0 -0.060025 -0.01005"
      rpy="0 0 0" />
    <parent
      link="hr_abad_link" />
    <child
      link="hr_upper_leg_link" />
    <axis
      xyz="0 1 0" />
    <limit
      lower="-1.75"
      upper="1.75"
      effort="0"
      velocity="0" />
  </joint>
  <link
    name="hr_lower_leg_link">
    <inertial>
      <origin
        xyz="-0.000684466152534924 -0.00120584717375838 -0.0295929737504189"
        rpy="0 0 0" />
      <mass
        value="0.0608832342299194" />
      <inertia
        ixx="7.56255610658338E-05"
        ixy="-3.1106421272234E-07"
        ixz="3.93850946067176E-06"
        iyy="7.29623913211001E-05"
        iyz="3.09026750236869E-06"
        izz="9.37165066726873E-06" />
    </inertial>
    <visual>
      <origin
        xyz="0 0 0"
        rpy="0 0 0" />
      <geometry>
        <mesh
          filename="package://champ_description/meshes/hr_lower_leg_link.STL" />
      </geometry>
      <material
        name="">
        <color
          rgba="0.0980392156862745 0.0980392156862745 0.0980392156862745 1" />
      </material>
    </visual>
    <collision>
      <origin
        xyz="0 0 0"
        rpy="0 0 0" />
      <geometry>
        <mesh
          filename="package://champ_description/meshes/hr_lower_leg_link.STL" />
      </geometry>
    </collision>
  </link>
  <joint
    name="hr_knee_joint"
    type="revolute">
    <origin
      xyz="0.03 0 -0.107"
      rpy="0 0 0" />
    <parent
      link="hr_upper_leg_link" />
    <child
      link="hr_lower_leg_link" />
    <axis
      xyz="0 1 0" />
    <limit
      lower="-3.14"
      upper="0.0"
      effort="0"
      velocity="0" />
  </joint>
  <link
    name="hr_foot_link">
    <inertial>
      <origin
        xyz="-0.00268456051833096 3.34520542100147E-07 0.0113457595405904"
        rpy="0 0 0" />
      <mass
        value="0.00827881665716704" />
      <inertia
        ixx="8.22036221200533E-07"
        ixy="-3.12294267959481E-12"
        ixz="2.06223465353849E-07"
        iyy="1.04877001633807E-06"
        iyz="-3.16711397726354E-12"
        izz="1.31417688803059E-06" />
    </inertial>
    <visual>
      <origin
        xyz="0 0 0"
        rpy="0 0 0" />
      <geometry>
        <mesh
          filename="package://champ_description/meshes/hr_foot_link.STL" />
      </geometry>
      <material
        name="">
        <color
          rgba="0.792156862745098 0.819607843137255 0.933333333333333 1" />
      </material>
    </visual>
    <collision>
      <origin
        xyz="0 0 0"
        rpy="0 0 0" />
      <geometry>
        <mesh
          filename="package://champ_description/meshes/hr_foot_link.STL" />
      </geometry>
    </collision>
  </link>
  <joint
    name="hr_ankle_joint"
    type="fixed">
    <origin
      xyz="-0.00045854 -0.0015345 -0.13599"
      rpy="0 0 0" />
    <parent
      link="hr_lower_leg_link" />
    <child
      link="hr_foot_link" />
    <axis
      xyz="0 0 0" />
  </joint>
  <link
    name="hl_abad_link">
    <inertial>
      <origin
        xyz="0.00120777765743818 0.000970661413346577 -0.00678019795796969"
        rpy="0 0 0" />
      <mass
        value="0.0892651030828233" />
      <inertia
        ixx="3.07213595919651E-05"
        ixy="-1.4613115515713E-12"
        ixz="3.65337843088021E-07"
        iyy="4.02109825847124E-05"
        iyz="1.44335870495851E-07"
        izz="1.62795585629666E-05" />
    </inertial>
    <visual>
      <origin
        xyz="0 0 0"
        rpy="0 0 0" />
      <geometry>
        <mesh
          filename="package://champ_description/meshes/hl_abad_link.STL" />
      </geometry>
      <material
        name="">
        <color
          rgba="0.792156862745098 0.819607843137255 0.933333333333333 1" />
      </material>
    </visual>
    <collision>
      <origin
        xyz="0 0 0"
        rpy="0 0 0" />
      <geometry>
        <mesh
          filename="package://champ_description/meshes/hl_abad_link.STL" />
      </geometry>
    </collision>
  </link>
  <joint
    name="hl_abad_joint"
    type="revolute">
    <origin
      xyz="-0.090715 0.039 0"
      rpy="0 0 0" />
    <parent
      link="base_link" />
    <child
      link="hl_abad_link" />
    <axis
      xyz="1 0 0" />
    <limit
      lower="-0.67"
      upper="0.85"
      effort="0"
      velocity="0" />
  </joint>
  <link
    name="hl_upper_leg_linnk">
    <inertial>
      <origin
        xyz="0.00168915447041158 -0.00225396606205499 -0.0395211076508124"
        rpy="0 0 0" />
      <mass
        value="0.139780014938308" />
      <inertia
        ixx="0.000109810306663954"
        ixy="-1.50279269981787E-06"
        ixz="-6.71658677153372E-07"
        iyy="0.000103459683396638"
        iyz="-9.66447756313517E-07"
        izz="2.8420673207803E-05" />
    </inertial>
    <visual>
      <origin
        xyz="0 0 0"
        rpy="0 0 0" />
      <geometry>
        <mesh
          filename="package://champ_description/meshes/hl_upper_leg_linnk.STL" />
      </geometry>
      <material
        name="">
        <color
          rgba="0.792156862745098 0.819607843137255 0.933333333333333 1" />
      </material>
    </visual>
    <collision>
      <origin
        xyz="0 0 0"
        rpy="0 0 0" />
      <geometry>
        <mesh
          filename="package://champ_description/meshes/hl_upper_leg_linnk.STL" />
      </geometry>
    </collision>
  </link>
  <joint
    name="hl_hip_joint"
    type="revolute">
    <origin
      xyz="0 0.06015 -0.01005"
      rpy="0 0 0" />
    <parent
      link="hl_abad_link" />
    <child
      link="hl_upper_leg_linnk" />
    <axis
      xyz="0 1 0" />
    <limit
      lower="-1.75"
      upper="1.75"
      effort="0"
      velocity="0" />
  </joint>
  <link
    name="hl_lower_leg_link">
    <inertial>
      <origin
        xyz="-0.000684437633580115 0.00133084764717366 -0.0295930592825451"
        rpy="0 0 0" />
      <mass
        value="0.0608832511150628" />
      <inertia
        ixx="7.56254687110168E-05"
        ixy="3.11067704123536E-07"
        ixz="3.93848857198344E-06"
        iyy="7.29622948511221E-05"
        iyz="-3.09027756281844E-06"
        izz="9.37164799604582E-06" />
    </inertial>
    <visual>
      <origin
        xyz="0 0 0"
        rpy="0 0 0" />
      <geometry>
        <mesh
          filename="package://champ_description/meshes/hl_lower_leg_link.STL" />
      </geometry>
      <material
        name="">
        <color
          rgba="0.0980392156862745 0.0980392156862745 0.0980392156862745 1" />
      </material>
    </visual>
    <collision>
      <origin
        xyz="0 0 0"
        rpy="0 0 0" />
      <geometry>
        <mesh
          filename="package://champ_description/meshes/hl_lower_leg_link.STL" />
      </geometry>
    </collision>
  </link>
  <joint
    name="hl_knee_joint"
    type="revolute">
    <origin
      xyz="0.03 0 -0.107"
      rpy="0 0 0" />
    <parent
      link="hl_upper_leg_linnk" />
    <child
      link="hl_lower_leg_link" />
    <axis
      xyz="0 1 0" />
    <limit
      lower="-3.14"
      upper="0.0"
      effort="0"
      velocity="0" />
  </joint>
  <link
    name="hl_foot_link">
    <inertial>
      <origin
        xyz="-0.00268456051833151 3.3452054221117E-07 0.0113457595405927"
        rpy="0 0 0" />
      <mass
        value="0.00827881665716705" />
      <inertia
        ixx="8.22036221200533E-07"
        ixy="-3.12294267891755E-12"
        ixz="2.06223465353849E-07"
        iyy="1.04877001633807E-06"
        iyz="-3.16711397746052E-12"
        izz="1.31417688803059E-06" />
    </inertial>
    <visual>
      <origin
        xyz="0 0 0"
        rpy="0 0 0" />
      <geometry>
        <mesh
          filename="package://champ_description/meshes/hl_foot_link.STL" />
      </geometry>
      <material
        name="">
        <color
          rgba="0.792156862745098 0.819607843137255 0.933333333333333 1" />
      </material>
    </visual>
    <collision>
      <origin
        xyz="0 0 0"
        rpy="0 0 0" />
      <geometry>
        <mesh
          filename="package://champ_description/meshes/hl_foot_link.STL" />
      </geometry>
    </collision>
  </link>
  <joint
    name="hl_ankle_joint"
    type="fixed">
    <origin
      xyz="-0.00045855 0.0016595 -0.13599"
      rpy="0 0 0" />
    <parent
      link="hl_lower_leg_link" />
    <child
      link="hl_foot_link" />
    <axis
      xyz="0 0 0" />
  </joint>
</robot>
